Workbook

Sheet INICIO
A1: VENDA GERAL 2026
A3: RENAN | E3: LUINE
A4: CLIENTE | B4: VALOR DE COMPRA TOTAL | C4: COMISSÃO | E4: CLIENTE | F4: VALOR DE COMPRA TOTAL | G4: COMISSÃO
A5: + BAZAR | B5: ='+ BAZAR'!G92 -> 0 | C5: ='+ BAZAR'!H93 -> 0 | E5: JHAMBA LE COOK | F5: ='JHAMBA LE COOK'!G92 -> 0 | G5: ='JHAMBA LE COOK'!H93 -> 0
A6: 2H VARIEDADES | B6: ='2H VARIEDADES'!G92 -> 0 | C6: ='2H VARIEDADES'!H93 -> 0 | E6: POESY AVIAMENTOS 0001-37 | F6: ='POESY AVIAMENTOS 0001-37'!G92 -> 0 | G6: ='POESY AVIAMENTOS 0001-37'!H93 -> 0
A7: ALJATEC ELETRICA | B7: =ALJATEC!G92 -> 0 | C7: =ALJATEC!H93 -> 0 | E7: POESY AVIAMENTOS 0001-83 | F7: ='POESY AVIAMENTOS 0001-83'!G92 -> 0 | G7: ='POESY AVIAMENTOS 0001-83'!H93 -> 0
A8: AMEI COMERCIO | B8: ='AMEI COMERCIO'!G92 -> 0 | C8: ='AMEI COMERCIO'!H93 -> 0 | E8: MKS COMERCIO | F8: ='MKS COMERCIO'!G92 -> 0 | G8: ='MKS COMERCIO'!H93 -> 0
A9: BELLA FIFI | B9: ='BELL FIFI'!G92 -> 0 | C9: ='BELL FIFI'!H93 -> 0
A10: CASA MIMO | B10: ='CASA MIMO'!G92 -> 0 | C10: ='CASA MIMO'!H93 -> 0
A11: CELL SOLLUTION | B11: ='CELL SOLLUTIONS'!G98 -> 0 | C11: ='CELL SOLLUTIONS'!H99 -> 0
A12: COMERCIAL BRAS RAIMUNDO | B12: ='COM. BRAS RAIMUNDO'!G92 -> 0 | C12: ='COM. BRAS RAIMUNDO'!H93 -> 0
A13: COMERCIAL MARTINS E MARTINS | B13: ='COM. MARTINS E MARTINS'!G92 -> 0 | C13: ='COM. MARTINS E MARTINS'!H93 -> 0
A14: COMERCIAL RONDONIA | B14: ='COMERCIAL RONDONIA'!G92 -> 0 | C14: ='COMERCIAL RONDONIA'!H93 -> 0
A15: C R DOS SANTOS | B15: ='C R DOS SANTOS'!G92 -> 0 | C15: ='C R DOS SANTOS'!H93 -> 0
A16: CRIS KING BIJU | B16: ='CRIS KING BIJU'!G92 -> 0 | C16: ='CRIS KING BIJU'!H93 -> 0
A17: CRIS MODAS TUPÃ | B17: ='CRIS MODAS'!G92 -> 0 | C17: ='CRIS MODAS'!H93 -> 0
A18: DECAZZA COM | B18: ='DECAZZA COM'!G92 -> 0 | C18: ='DECAZZA COM'!H93 -> 0
A19: DF COMERCIO | B19: ='DF COMERCIO'!G92 -> 0 | C19: ='DF COMERCIO'!H93 -> 0
A20: D.TSIANG | B20: =D.TSIANG!G92 -> 0 | C20: =D.TSIANG!H93 -> 0
A21: DELL REI | B21: ='DELL REI'!G92 -> 0 | C21: ='DELL REI'!H93 -> 0
A22: DISTRIBUIDORA GOMES LISBOA | B22: ='DISTR. GOMES LISBOA'!G92 -> 0 | C22: ='DISTR. GOMES LISBOA'!H93 -> 0
A23: EMBALEME COMERCIO | B23: ='EMBALEME COMERCIO'!G92 -> 0 | C23: ='EMBALEME COMERCIO'!H93 -> 0
A24: ERICA SHIRLEY | B24: ='ERICA SHIRLEY'!G92 -> 0 | C24: ='ERICA SHIRLEY'!H93 -> 0
A25: EVELINY MARIA | B25: ='EVELINY MARIA'!G92 -> 0 | C25: ='EVELINY MARIA'!H93 -> 0
A26: ELINETE JARDIM | B26: ='ELINETE JARDIM'!G92 -> 0 | C26: ='ELINETE JARDIM'!H93 -> 0
A27: FEST SHOW | B27: ='FEST SHOW'!G92 -> 0 | C27: ='FEST SHOW'!H93 -> 0
A28: FLAMBOYAN | B28: ='FLAMBOYAN '!G131 -> 0 | C28: ='FLAMBOYAN '!H132 -> 0
A29: FLAVIA COMERCIO | B29: ='FLÁVIA COMERCIO'!G92 -> 0 | C29: ='FLÁVIA COMERCIO'!H93 -> 0
A30: FLAP KIDS | B30: ='FLAP KIDS'!G92 -> 0 | C30: ='FLAP KIDS'!H93 -> 0
A31: FRANK PAPELARIA | B31: ='FRANK PAPELARIA'!G92 -> 0 | C31: ='FRANK PAPELARIA'!H93 -> 0
A32: GETULIO LIRA | B32: ='GETULIO LIRA'!G92 -> 0 | C32: ='GETULIO LIRA'!H93 -> 0
A33: GIULIANA CHRISTIELLE | B33: ='GIULIANA CHRISTIELLE'!G92 -> 0 | C33: ='GIULIANA CHRISTIELLE'!H93 -> 0
A34: IPED INSTITUTO | B34: =IPED!G92 -> 0 | C34: =IPED!H93 -> 0
A35: IVANETE JATAI | B35: ='IVANETE JATAI'!G92 -> 0 | C35: ='IVANETE JATAI'!H93 -> 0
A36: JANDERRUBEM | B36: =JANDERRUBEM!G92 -> 0 | C36: =JANDERRUBEM!H93 -> 0
A37: JANE STER(EDAC) | B37: ='JANE STER'!G92 -> 0 | C37: ='JANE STER'!H93 -> 0
A38: J L A HUNCA ME | B38: ='J L A HUNCA'!G92 -> 0 | C38: ='J L A HUNCA'!H93 -> 0
A39: KMRG | B39: =KMRG!G92 -> 0 | C39: =KMRG!H93 -> 0
A40: L. SOUZA MARTINS | B40: ='L. SOUZA'!G92 -> 0 | C40: ='L. SOUZA'!H93 -> 0
A41: LACORDAIRE TELES | B41: ='LACORDAIRE TELES'!G92 -> 0 | C41: ='LACORDAIRE TELES'!H93 -> 0
...

Sheet C R DOS SANTOS
A1: Data | C1: Fornecedor | D1: Pedido | E1: NFE | F1: Valor | H1: Comissão
A2: Compra | F2: Compra | H2: =G3*5% -> 0
A3: Faturamento | F3: Faturamento
J4: VOLTAR
A5: Compra | F5: Compra | H5: =G6*5% -> 0
A6: Faturamento | F6: Faturamento
A8: Compra | F8: Compra | H8: =G9*5% -> 0
A9: Faturamento | F9: Faturamento
A11: Compra | F11: Compra | H11: =G12*5% -> 0
A12: Faturamento | F12: Faturamento
A14: Compra | F14: Compra | H14: =G15*5% -> 0
A15: Faturamento | F15: Faturamento
A17: Compra | F17: Compra | H17: =G18*5% -> 0
A18: Faturamento | F18: Faturamento
A20: Compra | F20: Compra | H20: =G21*5% -> 0
A21: Faturamento | F21: Faturamento
A23: Compra | F23: Compra | H23: =G24*5% -> 0
A24: Faturamento | F24: Faturamento
A26: Compra | F26: Compra | H26: =G27*5% -> 0
A27: Faturamento | F27: Faturamento
A29: Compra | F29: Compra | H29: =G30*5% -> 0
A30: Faturamento | F30: Faturamento
A32: Compra | F32: Compra | H32: =G33*5% -> 0
A33: Faturamento | F33: Faturamento
A35: Compra | F35: Compra | H35: =G36*5% -> 0
A36: Faturamento | F36: Faturamento
A38: Compra | F38: Compra | H38: =G39*5% -> 0
A39: Faturamento | F39: Faturamento
A41: Compra | F41: Compra | H41: =G42*5% -> 0
A42: Faturamento | F42: Faturamento
A44: Compra | F44: Compra | H44: =G45*5% -> 0
A45: Faturamento | F45: Faturamento
A47: Compra | F47: Compra | H47: =G48*5% -> 0
A48: Faturamento | F48: Faturamento
A50: Compra | F50: Compra | H50: =G51*5% -> 0
A51: Faturamento | F51: Faturamento
A53: Compra | F53: Compra | H53: =G54*5% -> 0
A54: Faturamento | F54: Faturamento
A56: Compra | F56: Compra | H56: =G57*5% -> 0
A57: Faturamento | F57: Faturamento
...

Sheet POESY AVIAMENTOS 0001-83
A1: Data | C1: Fornecedor | D1: Pedido | E1: NFE | F1: Valor | H1: Comissão
A2: Compra | F2: Compra | H2: =G3*6.88% -> 0
A3: Faturamento | F3: Faturamento
J4: VOLTAR
A5: Compra | F5: Compra | H5: =G6*5% -> 0
A6: Faturamento | F6: Faturamento
A8: Compra | F8: Compra | H8: =G9*5% -> 0
A9: Faturamento | F9: Faturamento
A11: Compra | F11: Compra | H11: =G12*5% -> 0
A12: Faturamento | F12: Faturamento
A14: Compra | F14: Compra | H14: =G15*5% -> 0
A15: Faturamento | F15: Faturamento
A17: Compra | F17: Compra | H17: =G18*5% -> 0
A18: Faturamento | F18: Faturamento
A20: Compra | F20: Compra | H20: =G21*5% -> 0
A21: Faturamento | F21: Faturamento
A23: Compra | F23: Compra | H23: =G24*5% -> 0
A24: Faturamento | F24: Faturamento
A26: Compra | F26: Compra | H26: =G27*5% -> 0
A27: Faturamento | F27: Faturamento
A29: Compra | F29: Compra | H29: =G30*5% -> 0
A30: Faturamento | F30: Faturamento
A32: Compra | F32: Compra | H32: =G33*5% -> 0
A33: Faturamento | F33: Faturamento
A35: Compra | F35: Compra | H35: =G36*5% -> 0
A36: Faturamento | F36: Faturamento
A38: Compra | F38: Compra | H38: =G39*5% -> 0
A39: Faturamento | F39: Faturamento
A41: Compra | F41: Compra | H41: =G42*5% -> 0
A42: Faturamento | F42: Faturamento
A44: Compra | F44: Compra | H44: =G45*5% -> 0
A45: Faturamento | F45: Faturamento
A47: Compra | F47: Compra | H47: =G48*5% -> 0
A48: Faturamento | F48: Faturamento
A50: Compra | F50: Compra | H50: =G51*5% -> 0
A51: Faturamento | F51: Faturamento
A53: Compra | F53: Compra | H53: =G54*5% -> 0
A54: Faturamento | F54: Faturamento
A56: Compra | F56: Compra | H56: =G57*5% -> 0
A57: Faturamento | F57: Faturamento
...

Sheet POESY AVIAMENTOS 0001-37
A1: Data | C1: Fornecedor | D1: Pedido | E1: NFE | F1: Valor | H1: Comissão
A2: Compra | F2: Compra | H2: =G3*5% -> 0
A3: Faturamento | F3: Faturamento
J4: VOLTAR
A5: Compra | F5: Compra | H5: =G6*5% -> 0
A6: Faturamento | F6: Faturamento
A8: Compra | F8: Compra | H8: =G9*4% -> 0
A9: Faturamento | F9: Faturamento
A11: Compra | F11: Compra | H11: =G12*5% -> 0
A12: Faturamento | F12: Faturamento
A14: Compra | F14: Compra | H14: =G15*5% -> 0
A15: Faturamento | F15: Faturamento
A17: Compra | F17: Compra | H17: =G18*5% -> 0
A18: Faturamento | F18: Faturamento
A20: Compra | F20: Compra | H20: =G21*5% -> 0
A21: Faturamento | F21: Faturamento
A23: Compra | F23: Compra | H23: =G24*5% -> 0
A24: Faturamento | F24: Faturamento
A26: Compra | F26: Compra | H26: =G27*5% -> 0
A27: Faturamento | F27: Faturamento
A29: Compra | F29: Compra | H29: =G30*5% -> 0
A30: Faturamento | F30: Faturamento
A32: Compra | F32: Compra | H32: =G33*5% -> 0
A33: Faturamento | F33: Faturamento
A35: Compra | F35: Compra | H35: =G36*5% -> 0
A36: Faturamento | F36: Faturamento
A38: Compra | F38: Compra | H38: =G39*5% -> 0
A39: Faturamento | F39: Faturamento
A41: Compra | F41: Compra | H41: =G42*5% -> 0
A42: Faturamento | F42: Faturamento
A44: Compra | F44: Compra | H44: =G45*5% -> 0
A45: Faturamento | F45: Faturamento
A47: Compra | F47: Compra | H47: =G48*5% -> 0
A48: Faturamento | F48: Faturamento
A50: Compra | F50: Compra | H50: =G51*5% -> 0
A51: Faturamento | F51: Faturamento
A53: Compra | F53: Compra | H53: =G54*5% -> 0
A54: Faturamento | F54: Faturamento
A56: Compra | F56: Compra | H56: =G57*5% -> 0
A57: Faturamento | F57: Faturamento
...

Sheet L. SOUZA
A1: Data | C1: Fornecedor | D1: Pedido | E1: NFE | F1: Valor | H1: Comissão
A2: Compra | F2: Compra | H2: =G3*5% -> 0
A3: Faturamento | F3: Faturamento
J4: VOLTAR
A5: Compra | F5: Compra | H5: =G6*5% -> 0
A6: Faturamento | F6: Faturamento
A8: Compra | F8: Compra | H8: =G9*4% -> 0
A9: Faturamento | F9: Faturamento
A11: Compra | F11: Compra | H11: =G12*5% -> 0
A12: Faturamento | F12: Faturamento
A14: Compra | F14: Compra | H14: =G15*5% -> 0
A15: Faturamento | F15: Faturamento
A17: Compra | F17: Compra | H17: =G18*5% -> 0
A18: Faturamento | F18: Faturamento
A20: Compra | F20: Compra | H20: =G21*5% -> 0
A21: Faturamento | F21: Faturamento
A23: Compra | F23: Compra | H23: =G24*5% -> 0
A24: Faturamento | F24: Faturamento
A26: Compra | F26: Compra | H26: =G27*5% -> 0
A27: Faturamento | F27: Faturamento
A29: Compra | F29: Compra | H29: =G30*5% -> 0
A30: Faturamento | F30: Faturamento
A32: Compra | F32: Compra | H32: =G33*5% -> 0
A33: Faturamento | F33: Faturamento
A35: Compra | F35: Compra | H35: =G36*5% -> 0
A36: Faturamento | F36: Faturamento
A38: Compra | F38: Compra | H38: =G39*5% -> 0
A39: Faturamento | F39: Faturamento
A41: Compra | F41: Compra | H41: =G42*5% -> 0
A42: Faturamento | F42: Faturamento
A44: Compra | F44: Compra | H44: =G45*5% -> 0
A45: Faturamento | F45: Faturamento
A47: Compra | F47: Compra | H47: =G48*5% -> 0
A48: Faturamento | F48: Faturamento
A50: Compra | F50: Compra | H50: =G51*5% -> 0
A51: Faturamento | F51: Faturamento
A53: Compra | F53: Compra | H53: =G54*5% -> 0
A54: Faturamento | F54: Faturamento
A56: Compra | F56: Compra | H56: =G57*5% -> 0
A57: Faturamento | F57: Faturamento
...

Sheet JHAMBA LE COOK
A1: Data | C1: Fornecedor | D1: Pedido | E1: NFE | F1: Valor | H1: Comissão
A2: Compra | F2: Compra | H2: =G3*1.6% -> 0
A3: Faturamento | F3: Faturamento
J4: VOLTAR
A5: Compra | F5: Compra | H5: =G6*5% -> 0
A6: Faturamento | F6: Faturamento
A8: Compra | F8: Compra | H8: =G9*4% -> 0
A9: Faturamento | F9: Faturamento
A11: Compra | F11: Compra | H11: =G12*5% -> 0
A12: Faturamento | F12: Faturamento
A14: Compra | F14: Compra | H14: =G15*5% -> 0
A15: Faturamento | F15: Faturamento
A17: Compra | F17: Compra | H17: =G18*5% -> 0
A18: Faturamento | F18: Faturamento
A20: Compra | F20: Compra | H20: =G21*5% -> 0
A21: Faturamento | F21: Faturamento
A23: Compra | F23: Compra | H23: =G24*5% -> 0
A24: Faturamento | F24: Faturamento
A26: Compra | F26: Compra | H26: =G27*5% -> 0
A27: Faturamento | F27: Faturamento
A29: Compra | F29: Compra | H29: =G30*5% -> 0
A30: Faturamento | F30: Faturamento
A32: Compra | F32: Compra | H32: =G33*5% -> 0
A33: Faturamento | F33: Faturamento
A35: Compra | F35: Compra | H35: =G36*5% -> 0
A36: Faturamento | F36: Faturamento
A38: Compra | F38: Compra | H38: =G39*5% -> 0
A39: Faturamento | F39: Faturamento
A41: Compra | F41: Compra | H41: =G42*5% -> 0
A42: Faturamento | F42: Faturamento
A44: Compra | F44: Compra | H44: =G45*5% -> 0
A45: Faturamento | F45: Faturamento
A47: Compra | F47: Compra | H47: =G48*5% -> 0
A48: Faturamento | F48: Faturamento
A50: Compra | F50: Compra | H50: =G51*5% -> 0
A51: Faturamento | F51: Faturamento
A53: Compra | F53: Compra | H53: =G54*5% -> 0
A54: Faturamento | F54: Faturamento
A56: Compra | F56: Compra | H56: =G57*5% -> 0
A57: Faturamento | F57: Faturamento
...

Sheet ELINETE JARDIM
A1: Data | C1: Fornecedor | D1: Pedido | E1: NFE | F1: Valor | H1: Comissão
A2: Compra | F2: Compra | H2: =G3*5% -> 0
A3: Faturamento | F3: Faturamento
J4: VOLTAR
A5: Compra | F5: Compra | H5: =G6*5% -> 0
A6: Faturamento | F6: Faturamento
A8: Compra | F8: Compra | H8: =G9*4% -> 0
A9: Faturamento | F9: Faturamento
A11: Compra | F11: Compra | H11: =G12*5% -> 0
A12: Faturamento | F12: Faturamento
A14: Compra | F14: Compra | H14: =G15*5% -> 0
A15: Faturamento | F15: Faturamento
A17: Compra | F17: Compra | H17: =G18*5% -> 0
A18: Faturamento | F18: Faturamento
A20: Compra | F20: Compra | H20: =G21*5% -> 0
A21: Faturamento | F21: Faturamento
A23: Compra | F23: Compra | H23: =G24*5% -> 0
A24: Faturamento | F24: Faturamento
A26: Compra | F26: Compra | H26: =G27*5% -> 0
A27: Faturamento | F27: Faturamento
A29: Compra | F29: Compra | H29: =G30*5% -> 0
A30: Faturamento | F30: Faturamento
A32: Compra | F32: Compra | H32: =G33*5% -> 0
A33: Faturamento | F33: Faturamento
A35: Compra | F35: Compra | H35: =G36*5% -> 0
A36: Faturamento | F36: Faturamento
A38: Compra | F38: Compra | H38: =G39*5% -> 0
A39: Faturamento | F39: Faturamento
A41: Compra | F41: Compra | H41: =G42*5% -> 0
A42: Faturamento | F42: Faturamento
A44: Compra | F44: Compra | H44: =G45*5% -> 0
A45: Faturamento | F45: Faturamento
A47: Compra | F47: Compra | H47: =G48*5% -> 0
A48: Faturamento | F48: Faturamento
A50: Compra | F50: Compra | H50: =G51*5% -> 0
A51: Faturamento | F51: Faturamento
A53: Compra | F53: Compra | H53: =G54*5% -> 0
A54: Faturamento | F54: Faturamento
A56: Compra | F56: Compra | H56: =G57*5% -> 0
A57: Faturamento | F57: Faturamento
...

Sheet SAMUAH
A1: Data | C1: Fornecedor | D1: Pedido | E1: NFE | F1: Valor | H1: Comissão
A2: Compra | F2: Compra | H2: =G3*5% -> 0
A3: Faturamento | F3: Faturamento
J4: VOLTAR
A5: Compra | F5: Compra | H5: =G6*5% -> 0
A6: Faturamento | F6: Faturamento
A8: Compra | F8: Compra | H8: =G9*4% -> 0
A9: Faturamento | F9: Faturamento
A11: Compra | F11: Compra | H11: =G12*5% -> 0
A12: Faturamento | F12: Faturamento
A14: Compra | F14: Compra | H14: =G15*5% -> 0
A15: Faturamento | F15: Faturamento
A17: Compra | F17: Compra | H17: =G18*5% -> 0
A18: Faturamento | F18: Faturamento
A20: Compra | F20: Compra | H20: =G21*5% -> 0
A21: Faturamento | F21: Faturamento
A23: Compra | F23: Compra | H23: =G24*5% -> 0
A24: Faturamento | F24: Faturamento
A26: Compra | F26: Compra | H26: =G27*5% -> 0
A27: Faturamento | F27: Faturamento
A29: Compra | F29: Compra | H29: =G30*5% -> 0
A30: Faturamento | F30: Faturamento
A32: Compra | F32: Compra | H32: =G33*5% -> 0
A33: Faturamento | F33: Faturamento
A35: Compra | F35: Compra | H35: =G36*5% -> 0
A36: Faturamento | F36: Faturamento
A38: Compra | F38: Compra | H38: =G39*5% -> 0
A39: Faturamento | F39: Faturamento
A41: Compra | F41: Compra | H41: =G42*5% -> 0
A42: Faturamento | F42: Faturamento
A44: Compra | F44: Compra | H44: =G45*5% -> 0
A45: Faturamento | F45: Faturamento
A47: Compra | F47: Compra | H47: =G48*5% -> 0
A48: Faturamento | F48: Faturamento
A50: Compra | F50: Compra | H50: =G51*5% -> 0
A51: Faturamento | F51: Faturamento
A53: Compra | F53: Compra | H53: =G54*5% -> 0
A54: Faturamento | F54: Faturamento
A56: Compra | F56: Compra | H56: =G57*5% -> 0
A57: Faturamento | F57: Faturamento
...

Sheet VALDIRENE DOS SANTOS
A1: Data | C1: Fornecedor | D1: Pedido | E1: NFE | F1: Valor | H1: Comissão
A2: Compra | F2: Compra | H2: =G3*5% -> 0
A3: Faturamento | F3: Faturamento
J4: VOLTAR
A5: Compra | F5: Compra | H5: =G6*5% -> 0
A6: Faturamento | F6: Faturamento
A8: Compra | F8: Compra | H8: =G9*4% -> 0
A9: Faturamento | F9: Faturamento
A11: Compra | F11: Compra | H11: =G12*5% -> 0
A12: Faturamento | F12: Faturamento
A14: Compra | F14: Compra | H14: =G15*5% -> 0
A15: Faturamento | F15: Faturamento
A17: Compra | F17: Compra | H17: =G18*5% -> 0
A18: Faturamento | F18: Faturamento
A20: Compra | F20: Compra | H20: =G21*5% -> 0
A21: Faturamento | F21: Faturamento
A23: Compra | F23: Compra | H23: =G24*5% -> 0
A24: Faturamento | F24: Faturamento
A26: Compra | F26: Compra | H26: =G27*5% -> 0
A27: Faturamento | F27: Faturamento
A29: Compra | F29: Compra | H29: =G30*5% -> 0
A30: Faturamento | F30: Faturamento
A32: Compra | F32: Compra | H32: =G33*5% -> 0
A33: Faturamento | F33: Faturamento
A35: Compra | F35: Compra | H35: =G36*5% -> 0
A36: Faturamento | F36: Faturamento
A38: Compra | F38: Compra | H38: =G39*5% -> 0
A39: Faturamento | F39: Faturamento
A41: Compra | F41: Compra | H41: =G42*5% -> 0
A42: Faturamento | F42: Faturamento
A44: Compra | F44: Compra | H44: =G45*5% -> 0
A45: Faturamento | F45: Faturamento
A47: Compra | F47: Compra | H47: =G48*5% -> 0
A48: Faturamento | F48: Faturamento
A50: Compra | F50: Compra | H50: =G51*5% -> 0
A51: Faturamento | F51: Faturamento
A53: Compra | F53: Compra | H53: =G54*5% -> 0
A54: Faturamento | F54: Faturamento
A56: Compra | F56: Compra | H56: =G57*5% -> 0
A57: Faturamento | F57: Faturamento
...

Sheet KMRG
A1: Data | C1: Fornecedor | D1: Pedido | E1: NFE | F1: Valor | H1: Comissão
A2: Compra | F2: Compra | H2: =G3*5% -> 0
A3: Faturamento | F3: Faturamento
J4: VOLTAR
A5: Compra | F5: Compra | H5: =G6*5% -> 0
A6: Faturamento | F6: Faturamento
A8: Compra | F8: Compra | H8: =G9*4% -> 0
A9: Faturamento | F9: Faturamento
A11: Compra | F11: Compra | H11: =G12*5% -> 0
A12: Faturamento | F12: Faturamento
A14: Compra | F14: Compra | H14: =G15*5% -> 0
A15: Faturamento | F15: Faturamento
A17: Compra | F17: Compra | H17: =G18*5% -> 0
A18: Faturamento | F18: Faturamento
A20: Compra | F20: Compra | H20: =G21*5% -> 0
A21: Faturamento | F21: Faturamento
A23: Compra | F23: Compra | H23: =G24*5% -> 0
A24: Faturamento | F24: Faturamento
A26: Compra | F26: Compra | H26: =G27*5% -> 0
A27: Faturamento | F27: Faturamento
A29: Compra | F29: Compra | H29: =G30*5% -> 0
A30: Faturamento | F30: Faturamento
A32: Compra | F32: Compra | H32: =G33*5% -> 0
A33: Faturamento | F33: Faturamento
A35: Compra | F35: Compra | H35: =G36*5% -> 0
A36: Faturamento | F36: Faturamento
A38: Compra | F38: Compra | H38: =G39*5% -> 0
A39: Faturamento | F39: Faturamento
A41: Compra | F41: Compra | H41: =G42*5% -> 0
A42: Faturamento | F42: Faturamento
A44: Compra | F44: Compra | H44: =G45*5% -> 0
A45: Faturamento | F45: Faturamento
A47: Compra | F47: Compra | H47: =G48*5% -> 0
A48: Faturamento | F48: Faturamento
A50: Compra | F50: Compra | H50: =G51*5% -> 0
A51: Faturamento | F51: Faturamento
A53: Compra | F53: Compra | H53: =G54*5% -> 0
A54: Faturamento | F54: Faturamento
A56: Compra | F56: Compra | H56: =G57*5% -> 0
A57: Faturamento | F57: Faturamento
...

Sheet JANE STER
A1: Data | C1: Fornecedor | D1: Pedido | E1: NFE | F1: Valor | H1: Comissão
A2: Compra | F2: Compra | H2: =G3*5% -> 0
A3: Faturamento | F3: Faturamento
J4: VOLTAR
A5: Compra | F5: Compra | H5: =G6*5% -> 0
A6: Faturamento | F6: Faturamento
A8: Compra | F8: Compra | H8: =G9*4% -> 0
A9: Faturamento | F9: Faturamento
A11: Compra | F11: Compra | H11: =G12*5% -> 0
A12: Faturamento | F12: Faturamento
A14: Compra | F14: Compra | H14: =G15*5% -> 0
A15: Faturamento | F15: Faturamento
A17: Compra | F17: Compra | H17: =G18*5% -> 0
A18: Faturamento | F18: Faturamento
A20: Compra | F20: Compra | H20: =G21*5% -> 0
A21: Faturamento | F21: Faturamento
A23: Compra | F23: Compra | H23: =G24*5% -> 0
A24: Faturamento | F24: Faturamento
A26: Compra | F26: Compra | H26: =G27*5% -> 0
A27: Faturamento | F27: Faturamento
A29: Compra | F29: Compra | H29: =G30*5% -> 0
A30: Faturamento | F30: Faturamento
A32: Compra | F32: Compra | H32: =G33*5% -> 0
A33: Faturamento | F33: Faturamento
A35: Compra | F35: Compra | H35: =G36*5% -> 0
A36: Faturamento | F36: Faturamento
A38: Compra | F38: Compra | H38: =G39*5% -> 0
A39: Faturamento | F39: Faturamento
A41: Compra | F41: Compra | H41: =G42*5% -> 0
A42: Faturamento | F42: Faturamento
A44: Compra | F44: Compra | H44: =G45*5% -> 0
A45: Faturamento | F45: Faturamento
A47: Compra | F47: Compra | H47: =G48*5% -> 0
A48: Faturamento | F48: Faturamento
A50: Compra | F50: Compra | H50: =G51*5% -> 0
A51: Faturamento | F51: Faturamento
A53: Compra | F53: Compra | H53: =G54*5% -> 0
A54: Faturamento | F54: Faturamento
A56: Compra | F56: Compra | H56: =G57*5% -> 0
A57: Faturamento | F57: Faturamento
...

Sheet D.TSIANG
A1: Data | C1: Fornecedor | D1: Pedido | E1: NFE | F1: Valor | H1: Comissão
A2: Compra | F2: Compra | H2: =G3*5% -> 0
A3: Faturamento | F3: Faturamento
J4: VOLTAR
A5: Compra | F5: Compra | H5: =G6*5% -> 0
A6: Faturamento | F6: Faturamento
A8: Compra | F8: Compra | H8: =G9*4% -> 0
A9: Faturamento | F9: Faturamento
A11: Compra | F11: Compra | H11: =G12*5% -> 0
A12: Faturamento | F12: Faturamento
A14: Compra | F14: Compra | H14: =G15*5% -> 0
A15: Faturamento | F15: Faturamento
A17: Compra | F17: Compra | H17: =G18*5% -> 0
A18: Faturamento | F18: Faturamento
A20: Compra | F20: Compra | H20: =G21*5% -> 0
A21: Faturamento | F21: Faturamento
A23: Compra | F23: Compra | H23: =G24*5% -> 0
A24: Faturamento | F24: Faturamento
A26: Compra | F26: Compra | H26: =G27*5% -> 0
A27: Faturamento | F27: Faturamento
A29: Compra | F29: Compra | H29: =G30*5% -> 0
A30: Faturamento | F30: Faturamento
A32: Compra | F32: Compra | H32: =G33*5% -> 0
A33: Faturamento | F33: Faturamento
A35: Compra | F35: Compra | H35: =G36*5% -> 0
A36: Faturamento | F36: Faturamento
A38: Compra | F38: Compra | H38: =G39*5% -> 0
A39: Faturamento | F39: Faturamento
A41: Compra | F41: Compra | H41: =G42*5% -> 0
A42: Faturamento | F42: Faturamento
A44: Compra | F44: Compra | H44: =G45*5% -> 0
A45: Faturamento | F45: Faturamento
A47: Compra | F47: Compra | H47: =G48*5% -> 0
A48: Faturamento | F48: Faturamento
A50: Compra | F50: Compra | H50: =G51*5% -> 0
A51: Faturamento | F51: Faturamento
A53: Compra | F53: Compra | H53: =G54*5% -> 0
A54: Faturamento | F54: Faturamento
A56: Compra | F56: Compra | H56: =G57*5% -> 0
A57: Faturamento | F57: Faturamento
...

Sheet REALZÃO IMP
A1: Data | C1: Fornecedor | D1: Pedido | E1: NFE | F1: Valor | H1: Comissão
A2: Compra | F2: Compra | H2: =G3*5% -> 0
A3: Faturamento | F3: Faturamento
J4: VOLTAR
A5: Compra | F5: Compra | H5: =G6*5% -> 0
A6: Faturamento | F6: Faturamento
A8: Compra | F8: Compra | H8: =G9*4% -> 0
A9: Faturamento | F9: Faturamento
A11: Compra | F11: Compra | H11: =G12*5% -> 0
A12: Faturamento | F12: Faturamento
A14: Compra | F14: Compra | H14: =G15*5% -> 0
A15: Faturamento | F15: Faturamento
A17: Compra | F17: Compra | H17: =G18*5% -> 0
A18: Faturamento | F18: Faturamento
A20: Compra | F20: Compra | H20: =G21*5% -> 0
A21: Faturamento | F21: Faturamento
A23: Compra | F23: Compra | H23: =G24*5% -> 0
A24: Faturamento | F24: Faturamento
A26: Compra | F26: Compra | H26: =G27*5% -> 0
A27: Faturamento | F27: Faturamento
A29: Compra | F29: Compra | H29: =G30*5% -> 0
A30: Faturamento | F30: Faturamento
A32: Compra | F32: Compra | H32: =G33*5% -> 0
A33: Faturamento | F33: Faturamento
A35: Compra | F35: Compra | H35: =G36*5% -> 0
A36: Faturamento | F36: Faturamento
A38: Compra | F38: Compra | H38: =G39*5% -> 0
A39: Faturamento | F39: Faturamento
A41: Compra | F41: Compra | H41: =G42*5% -> 0
A42: Faturamento | F42: Faturamento
A44: Compra | F44: Compra | H44: =G45*5% -> 0
A45: Faturamento | F45: Faturamento
A47: Compra | F47: Compra | H47: =G48*5% -> 0
A48: Faturamento | F48: Faturamento
A50: Compra | F50: Compra | H50: =G51*5% -> 0
A51: Faturamento | F51: Faturamento
A53: Compra | F53: Compra | H53: =G54*5% -> 0
A54: Faturamento | F54: Faturamento
A56: Compra | F56: Compra | H56: =G57*5% -> 0
A57: Faturamento | F57: Faturamento
...

Sheet LOJAS MARIA
A1: X | C1: Fornecedor | D1: Pedido | E1: NFE | F1: Valor | H1: Comissão
A2: Compra | F2: Compra | H2: =G3*5% -> 0
A3: Faturamento | F3: Faturamento
J4: VOLTAR
A5: Compra | F5: Compra | H5: =G6*5% -> 0
A6: Faturamento | F6: Faturamento
A8: Compra | F8: Compra | H8: =G9*4% -> 0
A9: Faturamento | F9: Faturamento
A11: Compra | F11: Compra | H11: =G12*5% -> 0
A12: Faturamento | F12: Faturamento
A14: Compra | F14: Compra | H14: =G15*5% -> 0
A15: Faturamento | F15: Faturamento
A17: Compra | F17: Compra | H17: =G18*5% -> 0
A18: Faturamento | F18: Faturamento
A20: Compra | F20: Compra | H20: =G21*5% -> 0
A21: Faturamento | F21: Faturamento
A23: Compra | F23: Compra | H23: =G24*5% -> 0
A24: Faturamento | F24: Faturamento
A26: Compra | F26: Compra | H26: =G27*5% -> 0
A27: Faturamento | F27: Faturamento
A29: Compra | F29: Compra | H29: =G30*5% -> 0
A30: Faturamento | F30: Faturamento
A32: Compra | F32: Compra | H32: =G33*5% -> 0
A33: Faturamento | F33: Faturamento
A35: Compra | F35: Compra | H35: =G36*5% -> 0
A36: Faturamento | F36: Faturamento
A38: Compra | F38: Compra | H38: =G39*5% -> 0
A39: Faturamento | F39: Faturamento
A41: Compra | F41: Compra | H41: =G42*5% -> 0
A42: Faturamento | F42: Faturamento
A44: Compra | F44: Compra | H44: =G45*5% -> 0
A45: Faturamento | F45: Faturamento
A47: Compra | F47: Compra | H47: =G48*5% -> 0
A48: Faturamento | F48: Faturamento
A50: Compra | F50: Compra | H50: =G51*5% -> 0
A51: Faturamento | F51: Faturamento
A53: Compra | F53: Compra | H53: =G54*5% -> 0
A54: Faturamento | F54: Faturamento
A56: Compra | F56: Compra | H56: =G57*5% -> 0
A57: Faturamento | F57: Faturamento
...

Sheet V DOS SANTOS
A1: Data | C1: Fornecedor | D1: Pedido | E1: NFE | F1: Valor | H1: Comissão
A2: Compra | F2: Compra | H2: =G3*5% -> 0
A3: Faturamento | F3: Faturamento
J4: VOLTAR
A5: Compra | F5: Compra | H5: =G6*5% -> 0
A6: Faturamento | F6: Faturamento
A8: Compra | F8: Compra | H8: =G9*5% -> 0
A9: Faturamento | F9: Faturamento
A11: Compra | F11: Compra | H11: =G12*5% -> 0
A12: Faturamento | F12: Faturamento
A14: Compra | F14: Compra | H14: =G15*5% -> 0
A15: Faturamento | F15: Faturamento
A17: Compra | F17: Compra | H17: =G18*5% -> 0
A18: Faturamento | F18: Faturamento
A20: Compra | F20: Compra | H20: =G21*5% -> 0
A21: Faturamento | F21: Faturamento
A23: Compra | F23: Compra | H23: =G24*5% -> 0
A24: Faturamento | F24: Faturamento
A26: Compra | F26: Compra | H26: =G27*5% -> 0
A27: Faturamento | F27: Faturamento
A29: Compra | F29: Compra | H29: =G30*5% -> 0
A30: Faturamento | F30: Faturamento
A32: Compra | F32: Compra | H32: =G33*5% -> 0
A33: Faturamento | F33: Faturamento
A35: Compra | F35: Compra | H35: =G36*5% -> 0
A36: Faturamento | F36: Faturamento
A38: Compra | F38: Compra | H38: =G39*5% -> 0
A39: Faturamento | F39: Faturamento
A41: Compra | F41: Compra | H41: =G42*5% -> 0
A42: Faturamento | F42: Faturamento
A44: Compra | F44: Compra | H44: =G45*5% -> 0
A45: Faturamento | F45: Faturamento
A47: Compra | F47: Compra | H47: =G48*5% -> 0
A48: Faturamento | F48: Faturamento
A50: Compra | F50: Compra | H50: =G51*5% -> 0
A51: Faturamento | F51: Faturamento
A53: Compra | F53: Compra | H53: =G54*5% -> 0
A54: Faturamento | F54: Faturamento
A56: Compra | F56: Compra | H56: =G57*5% -> 0
A57: Faturamento | F57: Faturamento
...

Sheet NAVIO SERVIÇOS
A1: Data | C1: Fornecedor | D1: Pedido | E1: NFE | F1: Valor | H1: Comissão
A2: Compra | F2: Compra | H2: =G3*5% -> 0
A3: Faturamento | F3: Faturamento
J4: VOLTAR
A5: Compra | F5: Compra | H5: =G6*5% -> 0
A6: Faturamento | F6: Faturamento
A8: Compra | F8: Compra | H8: =G9*4% -> 0
A9: Faturamento | F9: Faturamento
A11: Compra | F11: Compra | H11: =G12*5% -> 0
A12: Faturamento | F12: Faturamento
A14: Compra | F14: Compra | H14: =G15*5% -> 0
A15: Faturamento | F15: Faturamento
A17: Compra | F17: Compra | H17: =G18*5% -> 0
A18: Faturamento | F18: Faturamento
A20: Compra | F20: Compra | H20: =G21*5% -> 0
A21: Faturamento | F21: Faturamento
A23: Compra | F23: Compra | H23: =G24*5% -> 0
A24: Faturamento | F24: Faturamento
A26: Compra | F26: Compra | H26: =G27*5% -> 0
A27: Faturamento | F27: Faturamento
A29: Compra | F29: Compra | H29: =G30*5% -> 0
A30: Faturamento | F30: Faturamento
A32: Compra | F32: Compra | H32: =G33*5% -> 0
A33: Faturamento | F33: Faturamento
A35: Compra | F35: Compra | H35: =G36*5% -> 0
A36: Faturamento | F36: Faturamento
A38: Compra | F38: Compra | H38: =G39*5% -> 0
A39: Faturamento | F39: Faturamento
A41: Compra | F41: Compra | H41: =G42*5% -> 0
A42: Faturamento | F42: Faturamento
A44: Compra | F44: Compra | H44: =G45*5% -> 0
A45: Faturamento | F45: Faturamento
A47: Compra | F47: Compra | H47: =G48*5% -> 0
A48: Faturamento | F48: Faturamento
A50: Compra | F50: Compra | H50: =G51*5% -> 0
A51: Faturamento | F51: Faturamento
A53: Compra | F53: Compra | H53: =G54*5% -> 0
A54: Faturamento | F54: Faturamento
A56: Compra | F56: Compra | H56: =G57*5% -> 0
A57: Faturamento | F57: Faturamento
...

Sheet GIULIANA CHRISTIELLE
A1: Data | C1: Fornecedor | D1: Pedido | E1: NFE | F1: Valor | H1: Comissão
A2: Compra | F2: Compra | H2: =G3*5% -> 0
A3: Faturamento | F3: Faturamento
J4: VOLTAR
A5: Compra | F5: Compra | H5: =G6*4% -> 0
A6: Faturamento | F6: Faturamento
A8: Compra | F8: Compra | H8: =G9*4% -> 0
A9: Faturamento | F9: Faturamento
A11: Compra | F11: Compra | H11: =G12*5% -> 0
A12: Faturamento | F12: Faturamento
A14: Compra | F14: Compra | H14: =G15*5% -> 0
A15: Faturamento | F15: Faturamento
A17: Compra | F17: Compra | H17: =G18*5% -> 0
A18: Faturamento | F18: Faturamento
A20: Compra | F20: Compra | H20: =G21*5% -> 0
A21: Faturamento | F21: Faturamento
A23: Compra | F23: Compra | H23: =G24*5% -> 0
A24: Faturamento | F24: Faturamento
A26: Compra | F26: Compra | H26: =G27*5% -> 0
A27: Faturamento | F27: Faturamento
A29: Compra | F29: Compra | H29: =G30*5% -> 0
A30: Faturamento | F30: Faturamento
A32: Compra | F32: Compra | H32: =G33*5% -> 0
A33: Faturamento | F33: Faturamento
A35: Compra | F35: Compra | H35: =G36*5% -> 0
A36: Faturamento | F36: Faturamento
A38: Compra | F38: Compra | H38: =G39*5% -> 0
A39: Faturamento | F39: Faturamento
A41: Compra | F41: Compra | H41: =G42*5% -> 0
A42: Faturamento | F42: Faturamento
A44: Compra | F44: Compra | H44: =G45*5% -> 0
A45: Faturamento | F45: Faturamento
A47: Compra | F47: Compra | H47: =G48*5% -> 0
A48: Faturamento | F48: Faturamento
A50: Compra | F50: Compra | H50: =G51*5% -> 0
A51: Faturamento | F51: Faturamento
A53: Compra | F53: Compra | H53: =G54*5% -> 0
A54: Faturamento | F54: Faturamento
A56: Compra | F56: Compra | H56: =G57*5% -> 0
A57: Faturamento | F57: Faturamento
...

Sheet TATIANE VEGAS
A1: Data | C1: Fornecedor | D1: Pedido | E1: NFE | F1: Valor | H1: Comissão
A2: Compra | F2: Compra | H2: =G3*4% -> 0
A3: Faturamento | F3: Faturamento
J4: VOLTAR
A5: Compra | F5: Compra | H5: =G6*4% -> 0
A6: Faturamento | F6: Faturamento
A8: Compra | F8: Compra | H8: =G9*4% -> 0
A9: Faturamento | F9: Faturamento
A11: Compra | F11: Compra | H11: =G12*5% -> 0
A12: Faturamento | F12: Faturamento
A14: Compra | F14: Compra | H14: =G15*5% -> 0
A15: Faturamento | F15: Faturamento
A17: Compra | F17: Compra | H17: =G18*5% -> 0
A18: Faturamento | F18: Faturamento
A20: Compra | F20: Compra | H20: =G21*5% -> 0
A21: Faturamento | F21: Faturamento
A23: Compra | F23: Compra | H23: =G24*5% -> 0
A24: Faturamento | F24: Faturamento
A26: Compra | F26: Compra | H26: =G27*5% -> 0
A27: Faturamento | F27: Faturamento
A29: Compra | F29: Compra | H29: =G30*5% -> 0
A30: Faturamento | F30: Faturamento
A32: Compra | F32: Compra | H32: =G33*5% -> 0
A33: Faturamento | F33: Faturamento
A35: Compra | F35: Compra | H35: =G36*5% -> 0
A36: Faturamento | F36: Faturamento
A38: Compra | F38: Compra | H38: =G39*5% -> 0
A39: Faturamento | F39: Faturamento
A41: Compra | F41: Compra | H41: =G42*5% -> 0
A42: Faturamento | F42: Faturamento
A44: Compra | F44: Compra | H44: =G45*5% -> 0
A45: Faturamento | F45: Faturamento
A47: Compra | F47: Compra | H47: =G48*5% -> 0
A48: Faturamento | F48: Faturamento
A50: Compra | F50: Compra | H50: =G51*5% -> 0
A51: Faturamento | F51: Faturamento
A53: Compra | F53: Compra | H53: =G54*5% -> 0
A54: Faturamento | F54: Faturamento
A56: Compra | F56: Compra | H56: =G57*5% -> 0
A57: Faturamento | F57: Faturamento
...

Sheet IPED
A1: Data | C1: Fornecedor | D1: Pedido | E1: NFE | F1: Valor | H1: Comissão
A2: Compra | F2: Compra | H2: =G3*2.5% -> 0
A3: Faturamento | F3: Faturamento
J4: VOLTAR
A5: Compra | F5: Compra | H5: =G6*2.5% -> 0
A6: Faturamento | F6: Faturamento
A8: Compra | F8: Compra | H8: =G9*2.5% -> 0
A9: Faturamento | F9: Faturamento
A11: Compra | F11: Compra | H11: =G12*2.5% -> 0
A12: Faturamento | F12: Faturamento
A14: Compra | F14: Compra | H14: =G15*5% -> 0
A15: Faturamento | F15: Faturamento
A17: Compra | F17: Compra | H17: =G18*5% -> 0
A18: Faturamento | F18: Faturamento
A20: Compra | F20: Compra | H20: =G21*5% -> 0
A21: Faturamento | F21: Faturamento
A23: Compra | F23: Compra | H23: =G24*5% -> 0
A24: Faturamento | F24: Faturamento
A26: Compra | F26: Compra | H26: =G27*5% -> 0
A27: Faturamento | F27: Faturamento
A29: Compra | F29: Compra | H29: =G30*5% -> 0
A30: Faturamento | F30: Faturamento
A32: Compra | F32: Compra | H32: =G33*5% -> 0
A33: Faturamento | F33: Faturamento
A35: Compra | F35: Compra | H35: =G36*5% -> 0
A36: Faturamento | F36: Faturamento
A38: Compra | F38: Compra | H38: =G39*5% -> 0
A39: Faturamento | F39: Faturamento
A41: Compra | F41: Compra | H41: =G42*5% -> 0
A42: Faturamento | F42: Faturamento
A44: Compra | F44: Compra | H44: =G45*5% -> 0
A45: Faturamento | F45: Faturamento
A47: Compra | F47: Compra | H47: =G48*5% -> 0
A48: Faturamento | F48: Faturamento
A50: Compra | F50: Compra | H50: =G51*5% -> 0
A51: Faturamento | F51: Faturamento
A53: Compra | F53: Compra | H53: =G54*5% -> 0
A54: Faturamento | F54: Faturamento
A56: Compra | F56: Compra | H56: =G57*5% -> 0
A57: Faturamento | F57: Faturamento
...

Sheet ERICA SHIRLEY
A1: Data | C1: Fornecedor | D1: Pedido | E1: NFE | F1: Valor | H1: Comissão
A2: Compra | F2: Compra | H2: =G3*5% -> 0
A3: Faturamento | F3: Faturamento
J4: VOLTAR
A5: Compra | F5: Compra | H5: =G6*5% -> 0
A6: Faturamento | F6: Faturamento
A8: Compra | F8: Compra | H8: =G9*4% -> 0
A9: Faturamento | F9: Faturamento
A11: Compra | F11: Compra | H11: =G12*5% -> 0
A12: Faturamento | F12: Faturamento
A14: Compra | F14: Compra | H14: =G15*5% -> 0
A15: Faturamento | F15: Faturamento
A17: Compra | F17: Compra | H17: =G18*5% -> 0
A18: Faturamento | F18: Faturamento
A20: Compra | F20: Compra | H20: =G21*5% -> 0
A21: Faturamento | F21: Faturamento
A23: Compra | F23: Compra | H23: =G24*5% -> 0
A24: Faturamento | F24: Faturamento
A26: Compra | F26: Compra | H26: =G27*5% -> 0
A27: Faturamento | F27: Faturamento
A29: Compra | F29: Compra | H29: =G30*5% -> 0
A30: Faturamento | F30: Faturamento
A32: Compra | F32: Compra | H32: =G33*5% -> 0
A33: Faturamento | F33: Faturamento
A35: Compra | F35: Compra | H35: =G36*5% -> 0
A36: Faturamento | F36: Faturamento
A38: Compra | F38: Compra | H38: =G39*5% -> 0
A39: Faturamento | F39: Faturamento
A41: Compra | F41: Compra | H41: =G42*5% -> 0
A42: Faturamento | F42: Faturamento
A44: Compra | F44: Compra | H44: =G45*5% -> 0
A45: Faturamento | F45: Faturamento
A47: Compra | F47: Compra | H47: =G48*5% -> 0
A48: Faturamento | F48: Faturamento
A50: Compra | F50: Compra | H50: =G51*5% -> 0
A51: Faturamento | F51: Faturamento
A53: Compra | F53: Compra | H53: =G54*5% -> 0
A54: Faturamento | F54: Faturamento
A56: Compra | F56: Compra | H56: =G57*5% -> 0
A57: Faturamento | F57: Faturamento
...

Sheet J L A HUNCA
A1: Data | C1: Fornecedor | D1: Pedido | E1: NFE | F1: Valor | H1: Comissão
A2: Compra | F2: Compra | H2: =G3*5% -> 0
A3: Faturamento | F3: Faturamento
J4: Voltar ao Inicio
A5: Compra | F5: Compra | H5: =G6*5% -> 0
A6: Faturamento | F6: Faturamento
A8: Compra | F8: Compra | H8: =G9*4% -> 0
A9: Faturamento | F9: Faturamento
A11: Compra | F11: Compra | H11: =G12*5% -> 0
A12: Faturamento | F12: Faturamento
A14: Compra | F14: Compra | H14: =G15*5% -> 0
A15: Faturamento | F15: Faturamento
A17: Compra | F17: Compra | H17: =G18*5% -> 0
A18: Faturamento | F18: Faturamento
A20: Compra | F20: Compra | H20: =G21*5% -> 0
A21: Faturamento | F21: Faturamento
A23: Compra | F23: Compra | H23: =G24*5% -> 0
A24: Faturamento | F24: Faturamento
A26: Compra | F26: Compra | H26: =G27*5% -> 0
A27: Faturamento | F27: Faturamento
A29: Compra | F29: Compra | H29: =G30*5% -> 0
A30: Faturamento | F30: Faturamento
A32: Compra | F32: Compra | H32: =G33*5% -> 0
A33: Faturamento | F33: Faturamento
A35: Compra | F35: Compra | H35: =G36*5% -> 0
A36: Faturamento | F36: Faturamento
A38: Compra | F38: Compra | H38: =G39*5% -> 0
A39: Faturamento | F39: Faturamento
A41: Compra | F41: Compra | H41: =G42*5% -> 0
A42: Faturamento | F42: Faturamento
A44: Compra | F44: Compra | H44: =G45*5% -> 0
A45: Faturamento | F45: Faturamento
A47: Compra | F47: Compra | H47: =G48*5% -> 0
A48: Faturamento | F48: Faturamento
A50: Compra | F50: Compra | H50: =G51*5% -> 0
A51: Faturamento | F51: Faturamento
A53: Compra | F53: Compra | H53: =G54*5% -> 0
A54: Faturamento | F54: Faturamento
A56: Compra | F56: Compra | H56: =G57*5% -> 0
A57: Faturamento | F57: Faturamento
...

Sheet DF COMERCIO
A1: Data | C1: Fornecedor | D1: Pedido | E1: NFE | F1: Valor | H1: Comissão
A2: Compra | F2: Compra | H2: =G3*5% -> 0
A3: Faturamento | F3: Faturamento
J4: Voltar ao Inicio
A5: Compra | F5: Compra | H5: =G6*5% -> 0
A6: Faturamento | F6: Faturamento
A8: Compra | F8: Compra | H8: =G9*2% -> 0
A9: Faturamento | F9: Faturamento
A11: Compra | F11: Compra | H11: =G12*2% -> 0
A12: Faturamento | F12: Faturamento
A14: Compra | F14: Compra | H14: =G15*5% -> 0
A15: Faturamento | F15: Faturamento
A17: Compra | F17: Compra | H17: =G18*5% -> 0
A18: Faturamento | F18: Faturamento
A20: Compra | F20: Compra | H20: =G21*5% -> 0
A21: Faturamento | F21: Faturamento
A23: Compra | F23: Compra | H23: =G24*5% -> 0
A24: Faturamento | F24: Faturamento
A26: Compra | F26: Compra | H26: =G27*5% -> 0
A27: Faturamento | F27: Faturamento
A29: Compra | F29: Compra | H29: =G30*5% -> 0
A30: Faturamento | F30: Faturamento
A32: Compra | F32: Compra | H32: =G33*5% -> 0
A33: Faturamento | F33: Faturamento
A35: Compra | F35: Compra | H35: =G36*5% -> 0
A36: Faturamento | F36: Faturamento
A38: Compra | F38: Compra | H38: =G39*5% -> 0
A39: Faturamento | F39: Faturamento
A41: Compra | F41: Compra | H41: =G42*5% -> 0
A42: Faturamento | F42: Faturamento
A44: Compra | F44: Compra | H44: =G45*5% -> 0
A45: Faturamento | F45: Faturamento
A47: Compra | F47: Compra | H47: =G48*5% -> 0
A48: Faturamento | F48: Faturamento
A50: Compra | F50: Compra | H50: =G51*5% -> 0
A51: Faturamento | F51: Faturamento
A53: Compra | F53: Compra | H53: =G54*5% -> 0
A54: Faturamento | F54: Faturamento
A56: Compra | F56: Compra | H56: =G57*5% -> 0
A57: Faturamento | F57: Faturamento
...

Sheet EVELINY MARIA
A1: Data | C1: Fornecedor | D1: Pedido | E1: NFE | F1: Valor | H1: Comissão
A2: Compra | F2: Compra | H2: =G3*5% -> 0
A3: Faturamento | F3: Faturamento
J4: Voltar ao Inicio
A5: Compra | F5: Compra | H5: =G6*5% -> 0
A6: Faturamento | F6: Faturamento
A8: Compra | F8: Compra | H8: =G9*5% -> 0
A9: Faturamento | F9: Faturamento
A11: Compra | F11: Compra | H11: =G12*5% -> 0
A12: Faturamento | F12: Faturamento
A14: Compra | F14: Compra | H14: =G15*5% -> 0
A15: Faturamento | F15: Faturamento
A17: Compra | F17: Compra | H17: =G18*5% -> 0
A18: Faturamento | F18: Faturamento
A20: Compra | F20: Compra | H20: =G21*5% -> 0
A21: Faturamento | F21: Faturamento
A23: Compra | F23: Compra | H23: =G24*5% -> 0
A24: Faturamento | F24: Faturamento
A26: Compra | F26: Compra | H26: =G27*5% -> 0
A27: Faturamento | F27: Faturamento
A29: Compra | F29: Compra | H29: =G30*5% -> 0
A30: Faturamento | F30: Faturamento
A32: Compra | F32: Compra | H32: =G33*5% -> 0
A33: Faturamento | F33: Faturamento
A35: Compra | F35: Compra | H35: =G36*5% -> 0
A36: Faturamento | F36: Faturamento
A38: Compra | F38: Compra | H38: =G39*5% -> 0
A39: Faturamento | F39: Faturamento
A41: Compra | F41: Compra | H41: =G42*5% -> 0
A42: Faturamento | F42: Faturamento
A44: Compra | F44: Compra | H44: =G45*5% -> 0
A45: Faturamento | F45: Faturamento
A47: Compra | F47: Compra | H47: =G48*5% -> 0
A48: Faturamento | F48: Faturamento
A50: Compra | F50: Compra | H50: =G51*5% -> 0
A51: Faturamento | F51: Faturamento
A53: Compra | F53: Compra | H53: =G54*5% -> 0
A54: Faturamento | F54: Faturamento
A56: Compra | F56: Compra | H56: =G57*5% -> 0
A57: Faturamento | F57: Faturamento
...

Sheet MRC8
A1: Data | C1: Fornecedor | D1: Pedido | E1: NFE | F1: Valor | H1: Comissão
A2: Compra | F2: Compra | H2: =G3*5% -> 0
A3: Faturamento | F3: Faturamento
J4: Voltar ao Inicio
A5: Compra | F5: Compra | H5: =G6*5% -> 0
A6: Faturamento | F6: Faturamento
A8: Compra | F8: Compra | H8: =G9*5% -> 0
A9: Faturamento | F9: Faturamento
A11: Compra | F11: Compra | H11: =G12*5% -> 0
A12: Faturamento | F12: Faturamento
A14: Compra | F14: Compra | H14: =G15*5% -> 0
A15: Faturamento | F15: Faturamento
A17: Compra | F17: Compra | H17: =G18*5% -> 0
A18: Faturamento | F18: Faturamento
A20: Compra | F20: Compra | H20: =G21*5% -> 0
A21: Faturamento | F21: Faturamento
A23: Compra | F23: Compra | H23: =G24*5% -> 0
A24: Faturamento | F24: Faturamento
A26: Compra | F26: Compra | H26: =G27*5% -> 0
A27: Faturamento | F27: Faturamento
A29: Compra | F29: Compra | H29: =G30*5% -> 0
A30: Faturamento | F30: Faturamento
A32: Compra | F32: Compra | H32: =G33*5% -> 0
A33: Faturamento | F33: Faturamento
A35: Compra | F35: Compra | H35: =G36*5% -> 0
A36: Faturamento | F36: Faturamento
A38: Compra | F38: Compra | H38: =G39*5% -> 0
A39: Faturamento | F39: Faturamento
A41: Compra | F41: Compra | H41: =G42*5% -> 0
A42: Faturamento | F42: Faturamento
A44: Compra | F44: Compra | H44: =G45*5% -> 0
A45: Faturamento | F45: Faturamento
A47: Compra | F47: Compra | H47: =G48*5% -> 0
A48: Faturamento | F48: Faturamento
A50: Compra | F50: Compra | H50: =G51*5% -> 0
A51: Faturamento | F51: Faturamento
A53: Compra | F53: Compra | H53: =G54*5% -> 0
A54: Faturamento | F54: Faturamento
A56: Compra | F56: Compra | H56: =G57*5% -> 0
A57: Faturamento | F57: Faturamento
...

Sheet W.LIMA
A1: Data | C1: Fornecedor | D1: Pedido | E1: NFE | F1: Valor | H1: Comissão
A2: Compra | F2: Compra | H2: =G3*5% -> 0
A3: Faturamento | F3: Faturamento
J4: Voltar ao Inicio
A5: Compra | F5: Compra | H5: =G6*5% -> 0
A6: Faturamento | F6: Faturamento
A8: Compra | F8: Compra | H8: =G9*4% -> 0
A9: Faturamento | F9: Faturamento
A11: Compra | F11: Compra | H11: =G12*5% -> 0
A12: Faturamento | F12: Faturamento
A14: Compra | F14: Compra | H14: =G15*5% -> 0
A15: Faturamento | F15: Faturamento
A17: Compra | F17: Compra | H17: =G18*5% -> 0
A18: Faturamento | F18: Faturamento
A20: Compra | F20: Compra | H20: =G21*5% -> 0
A21: Faturamento | F21: Faturamento
A23: Compra | F23: Compra | H23: =G24*5% -> 0
A24: Faturamento | F24: Faturamento
A26: Compra | F26: Compra | H26: =G27*5% -> 0
A27: Faturamento | F27: Faturamento
A29: Compra | F29: Compra | H29: =G30*5% -> 0
A30: Faturamento | F30: Faturamento
A32: Compra | F32: Compra | H32: =G33*5% -> 0
A33: Faturamento | F33: Faturamento
A35: Compra | F35: Compra | H35: =G36*5% -> 0
A36: Faturamento | F36: Faturamento
A38: Compra | F38: Compra | H38: =G39*5% -> 0
A39: Faturamento | F39: Faturamento
A41: Compra | F41: Compra | H41: =G42*5% -> 0
A42: Faturamento | F42: Faturamento
A44: Compra | F44: Compra | H44: =G45*5% -> 0
A45: Faturamento | F45: Faturamento
A47: Compra | F47: Compra | H47: =G48*5% -> 0
A48: Faturamento | F48: Faturamento
A50: Compra | F50: Compra | H50: =G51*5% -> 0
A51: Faturamento | F51: Faturamento
A53: Compra | F53: Compra | H53: =G54*5% -> 0
A54: Faturamento | F54: Faturamento
A56: Compra | F56: Compra | H56: =G57*5% -> 0
A57: Faturamento | F57: Faturamento
...

Sheet REALZÃO MONICA
A1: Data | C1: Fornecedor | D1: Pedido | E1: NFE | F1: Valor | H1: Comissão
A2: Compra | F2: Compra | H2: =G3*3% -> 0
A3: Faturamento | F3: Faturamento
J4: Voltar ao Inicio
A5: Compra | F5: Compra | H5: =G6*5% -> 0
A6: Faturamento | F6: Faturamento
A8: Compra | F8: Compra | H8: =G9*4% -> 0
A9: Faturamento | F9: Faturamento
A11: Compra | F11: Compra | H11: =G12*5% -> 0
A12: Faturamento | F12: Faturamento
A14: Compra | F14: Compra | H14: =G15*5% -> 0
A15: Faturamento | F15: Faturamento
A17: Compra | F17: Compra | H17: =G18*5% -> 0
A18: Faturamento | F18: Faturamento
A20: Compra | F20: Compra | H20: =G21*5% -> 0
A21: Faturamento | F21: Faturamento
A23: Compra | F23: Compra | H23: =G24*5% -> 0
A24: Faturamento | F24: Faturamento
A26: Compra | F26: Compra | H26: =G27*5% -> 0
A27: Faturamento | F27: Faturamento
A29: Compra | F29: Compra | H29: =G30*5% -> 0
A30: Faturamento | F30: Faturamento
A32: Compra | F32: Compra | H32: =G33*5% -> 0
A33: Faturamento | F33: Faturamento
A35: Compra | F35: Compra | H35: =G36*5% -> 0
A36: Faturamento | F36: Faturamento
A38: Compra | F38: Compra | H38: =G39*5% -> 0
A39: Faturamento | F39: Faturamento
A41: Compra | F41: Compra | H41: =G42*5% -> 0
A42: Faturamento | F42: Faturamento
A44: Compra | F44: Compra | H44: =G45*5% -> 0
A45: Faturamento | F45: Faturamento
A47: Compra | F47: Compra | H47: =G48*5% -> 0
A48: Faturamento | F48: Faturamento
A50: Compra | F50: Compra | H50: =G51*5% -> 0
A51: Faturamento | F51: Faturamento
A53: Compra | F53: Compra | H53: =G54*5% -> 0
A54: Faturamento | F54: Faturamento
A56: Compra | F56: Compra | H56: =G57*5% -> 0
A57: Faturamento | F57: Faturamento
...

Sheet CASA MIMO
A1: Data | C1: Fornecedor | D1: Pedido | E1: NFE | F1: Valor | H1: Comissão
A2: Compra | F2: Compra | H2: =G3*2.5% -> 0
A3: Faturamento | F3: Faturamento
J4: Voltar ao Inicio
A5: Compra | F5: Compra | H5: =G6*5% -> 0
A6: Faturamento | F6: Faturamento
A8: Compra | F8: Compra | H8: =G9*5% -> 0
A9: Faturamento | F9: Faturamento
A11: Compra | F11: Compra | H11: =G12*5% -> 0
A12: Faturamento | F12: Faturamento
A14: Compra | F14: Compra | H14: =G15*5% -> 0
A15: Faturamento | F15: Faturamento
A17: Compra | F17: Compra | H17: =G18*5% -> 0
A18: Faturamento | F18: Faturamento
A20: Compra | F20: Compra | H20: =G21*5% -> 0
A21: Faturamento | F21: Faturamento
A23: Compra | F23: Compra | H23: =G24*5% -> 0
A24: Faturamento | F24: Faturamento
A26: Compra | F26: Compra | H26: =G27*5% -> 0
A27: Faturamento | F27: Faturamento
A29: Compra | F29: Compra | H29: =G30*5% -> 0
A30: Faturamento | F30: Faturamento
A32: Compra | F32: Compra | H32: =G33*5% -> 0
A33: Faturamento | F33: Faturamento
A35: Compra | F35: Compra | H35: =G36*5% -> 0
A36: Faturamento | F36: Faturamento
A38: Compra | F38: Compra | H38: =G39*5% -> 0
A39: Faturamento | F39: Faturamento
A41: Compra | F41: Compra | H41: =G42*5% -> 0
A42: Faturamento | F42: Faturamento
A44: Compra | F44: Compra | H44: =G45*5% -> 0
A45: Faturamento | F45: Faturamento
A47: Compra | F47: Compra | H47: =G48*5% -> 0
A48: Faturamento | F48: Faturamento
A50: Compra | F50: Compra | H50: =G51*5% -> 0
A51: Faturamento | F51: Faturamento
A53: Compra | F53: Compra | H53: =G54*5% -> 0
A54: Faturamento | F54: Faturamento
A56: Compra | F56: Compra | H56: =G57*5% -> 0
A57: Faturamento | F57: Faturamento
...

Sheet AMEI COMERCIO
A1: Data | C1: Fornecedor | D1: Pedido | E1: NFE | F1: Valor | H1: Comissão
A2: Compra | F2: Compra | H2: =G3*5% -> 0
A3: Faturamento | F3: Faturamento
J4: Voltar ao Inicio
A5: Compra | F5: Compra | H5: =G6*5% -> 0
A6: Faturamento | F6: Faturamento
A8: Compra | F8: Compra | H8: =G9*5% -> 0
A9: Faturamento | F9: Faturamento
A11: Compra | F11: Compra | H11: =G12*5% -> 0
A12: Faturamento | F12: Faturamento
A14: Compra | F14: Compra | H14: =G15*5% -> 0
A15: Faturamento | F15: Faturamento
A17: Compra | F17: Compra | H17: =G18*5% -> 0
A18: Faturamento | F18: Faturamento
A20: Compra | F20: Compra | H20: =G21*5% -> 0
A21: Faturamento | F21: Faturamento
A23: Compra | F23: Compra | H23: =G24*5% -> 0
A24: Faturamento | F24: Faturamento
A26: Compra | F26: Compra | H26: =G27*5% -> 0
A27: Faturamento | F27: Faturamento
A29: Compra | F29: Compra | H29: =G30*5% -> 0
A30: Faturamento | F30: Faturamento
A32: Compra | F32: Compra | H32: =G33*5% -> 0
A33: Faturamento | F33: Faturamento
A35: Compra | F35: Compra | H35: =G36*5% -> 0
A36: Faturamento | F36: Faturamento
A38: Compra | F38: Compra | H38: =G39*5% -> 0
A39: Faturamento | F39: Faturamento
A41: Compra | F41: Compra | H41: =G42*5% -> 0
A42: Faturamento | F42: Faturamento
A44: Compra | F44: Compra | H44: =G45*5% -> 0
A45: Faturamento | F45: Faturamento
A47: Compra | F47: Compra | H47: =G48*5% -> 0
A48: Faturamento | F48: Faturamento
A50: Compra | F50: Compra | H50: =G51*5% -> 0
A51: Faturamento | F51: Faturamento
A53: Compra | F53: Compra | H53: =G54*5% -> 0
A54: Faturamento | F54: Faturamento
A56: Compra | F56: Compra | H56: =G57*5% -> 0
A57: Faturamento | F57: Faturamento
...

Sheet FRANK PAPELARIA
A1: Data | C1: Fornecedor | D1: Pedido | E1: NFE | F1: Valor | H1: Comissão
A2: Compra | F2: Compra | H2: =G3*5% -> 0
A3: Faturamento | F3: Faturamento
J4: Voltar ao Inicio
A5: Compra | F5: Compra | H5: =G6*5% -> 0
A6: Faturamento | F6: Faturamento
A8: Compra | F8: Compra | H8: =G9*4% -> 0
A9: Faturamento | F9: Faturamento
A11: Compra | F11: Compra | H11: =G12*5% -> 0
A12: Faturamento | F12: Faturamento
A14: Compra | F14: Compra | H14: =G15*5% -> 0
A15: Faturamento | F15: Faturamento
A17: Compra | F17: Compra | H17: =G18*5% -> 0
A18: Faturamento | F18: Faturamento
A20: Compra | F20: Compra | H20: =G21*5% -> 0
A21: Faturamento | F21: Faturamento
A23: Compra | F23: Compra | H23: =G24*5% -> 0
A24: Faturamento | F24: Faturamento
A26: Compra | F26: Compra | H26: =G27*5% -> 0
A27: Faturamento | F27: Faturamento
A29: Compra | F29: Compra | H29: =G30*5% -> 0
A30: Faturamento | F30: Faturamento
A32: Compra | F32: Compra | H32: =G33*5% -> 0
A33: Faturamento | F33: Faturamento
A35: Compra | F35: Compra | H35: =G36*5% -> 0
A36: Faturamento | F36: Faturamento
A38: Compra | F38: Compra | H38: =G39*5% -> 0
A39: Faturamento | F39: Faturamento
A41: Compra | F41: Compra | H41: =G42*5% -> 0
A42: Faturamento | F42: Faturamento
A44: Compra | F44: Compra | H44: =G45*5% -> 0
A45: Faturamento | F45: Faturamento
A47: Compra | F47: Compra | H47: =G48*5% -> 0
A48: Faturamento | F48: Faturamento
A50: Compra | F50: Compra | H50: =G51*5% -> 0
A51: Faturamento | F51: Faturamento
A53: Compra | F53: Compra | H53: =G54*5% -> 0
A54: Faturamento | F54: Faturamento
A56: Compra | F56: Compra | H56: =G57*5% -> 0
A57: Faturamento | F57: Faturamento
...

Sheet W.CHUNMEI
A1: Data | C1: Fornecedor | D1: Pedido | E1: NFE | F1: Valor | H1: Comissão
A2: Compra | F2: Compra | H2: =G3*4% -> 0
A3: Faturamento | F3: Faturamento
J4: Voltar ao Inicio
A5: Compra | F5: Compra | H5: =G6*3% -> 0
A6: Faturamento | F6: Faturamento
A8: Compra | F8: Compra | H8: =G9*4% -> 0
A9: Faturamento | F9: Faturamento
A11: Compra | F11: Compra | H11: =G12*5% -> 0
A12: Faturamento | F12: Faturamento
A14: Compra | F14: Compra | H14: =G15*5% -> 0
A15: Faturamento | F15: Faturamento
A17: Compra | F17: Compra | H17: =G18*5% -> 0
A18: Faturamento | F18: Faturamento
A20: Compra | F20: Compra | H20: =G21*5% -> 0
A21: Faturamento | F21: Faturamento
A23: Compra | F23: Compra | H23: =G24*5% -> 0
A24: Faturamento | F24: Faturamento
A26: Compra | F26: Compra | H26: =G27*5% -> 0
A27: Faturamento | F27: Faturamento
A29: Compra | F29: Compra | H29: =G30*5% -> 0
A30: Faturamento | F30: Faturamento
A32: Compra | F32: Compra | H32: =G33*5% -> 0
A33: Faturamento | F33: Faturamento
A35: Compra | F35: Compra | H35: =G36*5% -> 0
A36: Faturamento | F36: Faturamento
A38: Compra | F38: Compra | H38: =G39*5% -> 0
A39: Faturamento | F39: Faturamento
A41: Compra | F41: Compra | H41: =G42*5% -> 0
A42: Faturamento | F42: Faturamento
A44: Compra | F44: Compra | H44: =G45*5% -> 0
A45: Faturamento | F45: Faturamento
A47: Compra | F47: Compra | H47: =G48*5% -> 0
A48: Faturamento | F48: Faturamento
A50: Compra | F50: Compra | H50: =G51*5% -> 0
A51: Faturamento | F51: Faturamento
A53: Compra | F53: Compra | H53: =G54*5% -> 0
A54: Faturamento | F54: Faturamento
A56: Compra | F56: Compra | H56: =G57*5% -> 0
A57: Faturamento | F57: Faturamento
...

Sheet JANDERRUBEM
A1: Data | C1: Fornecedor | D1: Pedido | E1: NFE | F1: Valor | H1: Comissão
A2: Compra | F2: Compra | H2: =G3*5% -> 0
A3: Faturamento | F3: Faturamento
J4: Voltar ao Inicio
A5: Compra | F5: Compra | H5: =G6*3% -> 0
A6: Faturamento | F6: Faturamento
A8: Compra | F8: Compra | H8: =G9*4% -> 0
A9: Faturamento | F9: Faturamento
A11: Compra | F11: Compra | H11: =G12*5% -> 0
A12: Faturamento | F12: Faturamento
A14: Compra | F14: Compra | H14: =G15*5% -> 0
A15: Faturamento | F15: Faturamento
A17: Compra | F17: Compra | H17: =G18*5% -> 0
A18: Faturamento | F18: Faturamento
A20: Compra | F20: Compra | H20: =G21*5% -> 0
A21: Faturamento | F21: Faturamento
A23: Compra | F23: Compra | H23: =G24*5% -> 0
A24: Faturamento | F24: Faturamento
A26: Compra | F26: Compra | H26: =G27*5% -> 0
A27: Faturamento | F27: Faturamento
A29: Compra | F29: Compra | H29: =G30*5% -> 0
A30: Faturamento | F30: Faturamento
A32: Compra | F32: Compra | H32: =G33*5% -> 0
A33: Faturamento | F33: Faturamento
A35: Compra | F35: Compra | H35: =G36*5% -> 0
A36: Faturamento | F36: Faturamento
A38: Compra | F38: Compra | H38: =G39*5% -> 0
A39: Faturamento | F39: Faturamento
A41: Compra | F41: Compra | H41: =G42*5% -> 0
A42: Faturamento | F42: Faturamento
A44: Compra | F44: Compra | H44: =G45*5% -> 0
A45: Faturamento | F45: Faturamento
A47: Compra | F47: Compra | H47: =G48*5% -> 0
A48: Faturamento | F48: Faturamento
A50: Compra | F50: Compra | H50: =G51*5% -> 0
A51: Faturamento | F51: Faturamento
A53: Compra | F53: Compra | H53: =G54*5% -> 0
A54: Faturamento | F54: Faturamento
A56: Compra | F56: Compra | H56: =G57*5% -> 0
A57: Faturamento | F57: Faturamento
...

Sheet BELL FIFI
A1: Data | C1: Fornecedor | D1: Pedido | E1: NFE | F1: Valor | H1: Comissão
A2: Compra | F2: Compra | H2: =G3*2% -> 0
A3: Faturamento | F3: Faturamento
J4: Voltar ao Inicio
A5: Compra | F5: Compra | H5: =G6*5% -> 0
A6: Faturamento | F6: Faturamento
A8: Compra | F8: Compra | H8: =G9*5% -> 0
A9: Faturamento | F9: Faturamento
A11: Compra | F11: Compra | H11: =G12*2% -> 0
A12: Faturamento | F12: Faturamento
A14: Compra | F14: Compra | H14: =G15*5% -> 0
A15: Faturamento | F15: Faturamento
A17: Compra | F17: Compra | H17: =G18*5% -> 0
A18: Faturamento | F18: Faturamento
A20: Compra | F20: Compra | H20: =G21*5% -> 0
A21: Faturamento | F21: Faturamento
A23: Compra | F23: Compra | H23: =G24*5% -> 0
A24: Faturamento | F24: Faturamento
A26: Compra | F26: Compra | H26: =G27*5% -> 0
A27: Faturamento | F27: Faturamento
A29: Compra | F29: Compra | H29: =G30*5% -> 0
A30: Faturamento | F30: Faturamento
A32: Compra | F32: Compra | H32: =G33*5% -> 0
A33: Faturamento | F33: Faturamento
A35: Compra | F35: Compra | H35: =G36*5% -> 0
A36: Faturamento | F36: Faturamento
A38: Compra | F38: Compra | H38: =G39*5% -> 0
A39: Faturamento | F39: Faturamento
A41: Compra | F41: Compra | H41: =G42*5% -> 0
A42: Faturamento | F42: Faturamento
A44: Compra | F44: Compra | H44: =G45*5% -> 0
A45: Faturamento | F45: Faturamento
A47: Compra | F47: Compra | H47: =G48*5% -> 0
A48: Faturamento | F48: Faturamento
A50: Compra | F50: Compra | H50: =G51*5% -> 0
A51: Faturamento | F51: Faturamento
A53: Compra | F53: Compra | H53: =G54*5% -> 0
A54: Faturamento | F54: Faturamento
A56: Compra | F56: Compra | H56: =G57*5% -> 0
A57: Faturamento | F57: Faturamento
...

Sheet SUPER PART
A1: Data | C1: Fornecedor | D1: Pedido | E1: NFE | F1: Valor | H1: Comissão
A2: Compra | F2: Compra | H2: =G3*4% -> 0
A3: Faturamento | F3: Faturamento
J4: Voltar ao Inicio
A5: Compra | F5: Compra | H5: =G6*3% -> 0
A6: Faturamento | F6: Faturamento
A8: Compra | F8: Compra | H8: =G9*4% -> 0
A9: Faturamento | F9: Faturamento
A11: Compra | F11: Compra | H11: =G12*5% -> 0
A12: Faturamento | F12: Faturamento
A14: Compra | F14: Compra | H14: =G15*5% -> 0
A15: Faturamento | F15: Faturamento
A17: Compra | F17: Compra | H17: =G18*5% -> 0
A18: Faturamento | F18: Faturamento
A20: Compra | F20: Compra | H20: =G21*5% -> 0
A21: Faturamento | F21: Faturamento
A23: Compra | F23: Compra | H23: =G24*5% -> 0
A24: Faturamento | F24: Faturamento
A26: Compra | F26: Compra | H26: =G27*5% -> 0
A27: Faturamento | F27: Faturamento
A29: Compra | F29: Compra | H29: =G30*5% -> 0
A30: Faturamento | F30: Faturamento
A32: Compra | F32: Compra | H32: =G33*5% -> 0
A33: Faturamento | F33: Faturamento
A35: Compra | F35: Compra | H35: =G36*5% -> 0
A36: Faturamento | F36: Faturamento
A38: Compra | F38: Compra | H38: =G39*5% -> 0
A39: Faturamento | F39: Faturamento
A41: Compra | F41: Compra | H41: =G42*5% -> 0
A42: Faturamento | F42: Faturamento
A44: Compra | F44: Compra | H44: =G45*5% -> 0
A45: Faturamento | F45: Faturamento
A47: Compra | F47: Compra | H47: =G48*5% -> 0
A48: Faturamento | F48: Faturamento
A50: Compra | F50: Compra | H50: =G51*5% -> 0
A51: Faturamento | F51: Faturamento
A53: Compra | F53: Compra | H53: =G54*5% -> 0
A54: Faturamento | F54: Faturamento
A56: Compra | F56: Compra | H56: =G57*5% -> 0
A57: Faturamento | F57: Faturamento
...

Sheet WRA
A1: Data | C1: Fornecedor | D1: Pedido | E1: NFE | F1: Valor | H1: Comissão
A2: Compra | F2: Compra | H2: =G3*4% -> 0
A3: Faturamento | F3: Faturamento
J4: Voltar ao Inicio
A5: Compra | F5: Compra | H5: =G6*3% -> 0
A6: Faturamento | F6: Faturamento
A8: Compra | F8: Compra | H8: =G9*4% -> 0
A9: Faturamento | F9: Faturamento
A11: Compra | F11: Compra | H11: =G12*5% -> 0
A12: Faturamento | F12: Faturamento
A14: Compra | F14: Compra | H14: =G15*5% -> 0
A15: Faturamento | F15: Faturamento
A17: Compra | F17: Compra | H17: =G18*5% -> 0
A18: Faturamento | F18: Faturamento
A20: Compra | F20: Compra | H20: =G21*5% -> 0
A21: Faturamento | F21: Faturamento
A23: Compra | F23: Compra | H23: =G24*5% -> 0
A24: Faturamento | F24: Faturamento
A26: Compra | F26: Compra | H26: =G27*5% -> 0
A27: Faturamento | F27: Faturamento
A29: Compra | F29: Compra | H29: =G30*5% -> 0
A30: Faturamento | F30: Faturamento
A32: Compra | F32: Compra | H32: =G33*5% -> 0
A33: Faturamento | F33: Faturamento
A35: Compra | F35: Compra | H35: =G36*5% -> 0
A36: Faturamento | F36: Faturamento
A38: Compra | F38: Compra | H38: =G39*5% -> 0
A39: Faturamento | F39: Faturamento
A41: Compra | F41: Compra | H41: =G42*5% -> 0
A42: Faturamento | F42: Faturamento
A44: Compra | F44: Compra | H44: =G45*5% -> 0
A45: Faturamento | F45: Faturamento
A47: Compra | F47: Compra | H47: =G48*5% -> 0
A48: Faturamento | F48: Faturamento
A50: Compra | F50: Compra | H50: =G51*5% -> 0
A51: Faturamento | F51: Faturamento
A53: Compra | F53: Compra | H53: =G54*5% -> 0
A54: Faturamento | F54: Faturamento
A56: Compra | F56: Compra | H56: =G57*5% -> 0
A57: Faturamento | F57: Faturamento
...

Sheet RAPPY TOYS
A1: Data | C1: Fornecedor | D1: Pedido | E1: NFE | F1: Valor | H1: Comissão
A2: Compra | F2: Compra | H2: =G3*4% -> 0
A3: Faturamento | F3: Faturamento
J4: Voltar ao Inicio
A5: Compra | F5: Compra | H5: =G6*3% -> 0
A6: Faturamento | F6: Faturamento
A8: Compra | F8: Compra | H8: =G9*4% -> 0
A9: Faturamento | F9: Faturamento
A11: Compra | F11: Compra | H11: =G12*5% -> 0
A12: Faturamento | F12: Faturamento
A14: Compra | F14: Compra | H14: =G15*5% -> 0
A15: Faturamento | F15: Faturamento
A17: Compra | F17: Compra | H17: =G18*5% -> 0
A18: Faturamento | F18: Faturamento
A20: Compra | F20: Compra | H20: =G21*5% -> 0
A21: Faturamento | F21: Faturamento
A23: Compra | F23: Compra | H23: =G24*5% -> 0
A24: Faturamento | F24: Faturamento
A26: Compra | F26: Compra | H26: =G27*5% -> 0
A27: Faturamento | F27: Faturamento
A29: Compra | F29: Compra | H29: =G30*5% -> 0
A30: Faturamento | F30: Faturamento
A32: Compra | F32: Compra | H32: =G33*5% -> 0
A33: Faturamento | F33: Faturamento
A35: Compra | F35: Compra | H35: =G36*5% -> 0
A36: Faturamento | F36: Faturamento
A38: Compra | F38: Compra | H38: =G39*5% -> 0
A39: Faturamento | F39: Faturamento
A41: Compra | F41: Compra | H41: =G42*5% -> 0
A42: Faturamento | F42: Faturamento
A44: Compra | F44: Compra | H44: =G45*5% -> 0
A45: Faturamento | F45: Faturamento
A47: Compra | F47: Compra | H47: =G48*5% -> 0
A48: Faturamento | F48: Faturamento
A50: Compra | F50: Compra | H50: =G51*5% -> 0
A51: Faturamento | F51: Faturamento
A53: Compra | F53: Compra | H53: =G54*5% -> 0
A54: Faturamento | F54: Faturamento
A56: Compra | F56: Compra | H56: =G57*5% -> 0
A57: Faturamento | F57: Faturamento
...

Sheet LACORDAIRE TELES
